2025-03-04 22:05:07,088 - INFO - ✅ Using GPU device 1.
2025-03-04 22:05:07,090 - ERROR - Unhandled exception occurred:
Traceback (most recent call last):
  File "converter_ex.py", line 17, in <module>
    from config import INPUT_DATA_PATHS, OUTPUT_DIRECTORIES  # ✅ config.py에서 설정 불러오기
  File "/caefs/user/mmingyeong/structura/Structura/src/config.py", line 68, in <module>
    os.makedirs(path, exist_ok=True)
  File "/home/users/mmingyeong/.conda/envs/mingyeong/lib/python3.7/os.py", line 213, in makedirs
    makedirs(head, exist_ok=exist_ok)
  File "/home/users/mmingyeong/.conda/envs/mingyeong/lib/python3.7/os.py", line 213, in makedirs
    makedirs(head, exist_ok=exist_ok)
  File "/home/users/mmingyeong/.conda/envs/mingyeong/lib/python3.7/os.py", line 213, in makedirs
    makedirs(head, exist_ok=exist_ok)
  [Previous line repeated 1 more time]
  File "/home/users/mmingyeong/.conda/envs/mingyeong/lib/python3.7/os.py", line 223, in makedirs
    mkdir(name, mode)
PermissionError: [Errno 13] Permission denied: '/path'
