2025-04-22 09:43:45,464 - ERROR - Unhandled exception occurred:
Traceback (most recent call last):
  File "/caefs/user/mmingyeong/structura/Structura/src/example/density_kde_seq_chunks/00_TestDensity.py", line 160, in <module>
    main()
  File "/caefs/user/mmingyeong/structura/Structura/src/example/density_kde_seq_chunks/00_TestDensity.py", line 132, in main
    dset = f.create_dataset("density_map", shape=(nx, ny, nz), dtype='float64',
  File "/home/users/mmingyeong/.conda/envs/new_env/lib/python3.10/site-packages/h5py/_hl/group.py", line 186, in create_dataset
    dsid = dataset.make_new_dset(group, shape, dtype, data, name, **kwds)
  File "/home/users/mmingyeong/.conda/envs/new_env/lib/python3.10/site-packages/h5py/_hl/dataset.py", line 74, in make_new_dset
    raise ValueError(errmsg)
ValueError: Chunk shape must not be greater than data shape in any dimension. (406, 406, 406) is not compatible with (250, 250, 250)
