2025-04-22 14:28:58,083 - ERROR - Unhandled exception occurred:
Traceback (most recent call last):
  File "/caefs/user/mmingyeong/structura/Structura/src/example/density_nufft_seq_chunks/00_TestDensity.py", line 123, in <module>
    main()
  File "/caefs/user/mmingyeong/structura/Structura/src/example/density_nufft_seq_chunks/00_TestDensity.py", line 107, in main
    density_mmap = kde.compute_density()
  File "/caefs/user/mmingyeong/structura/Structura/src/nufft_kde.py", line 110, in compute_density
    with h5py.File(save_hdf5_path, 'a') as f:
  File "/home/users/mmingyeong/.conda/envs/new_env/lib/python3.10/site-packages/h5py/_hl/files.py", line 539, in __init__
    name = filename_encode(name)
  File "/home/users/mmingyeong/.conda/envs/new_env/lib/python3.10/site-packages/h5py/_hl/compat.py", line 25, in filename_encode
    filename = fspath(filename)
TypeError: expected str, bytes or os.PathLike object, not bool
