2025-04-22 09:53:14,540 - ERROR - Unhandled exception occurred:
Traceback (most recent call last):
  File "/caefs/user/mmingyeong/structura/Structura/src/example/density_kde_seq_chunks/00_TestDensity.py", line 171, in <module>
    main()
  File "/caefs/user/mmingyeong/structura/Structura/src/example/density_kde_seq_chunks/00_TestDensity.py", line 141, in main
    with h5py.File(output_path, 'w') as f:
  File "/home/users/mmingyeong/.conda/envs/new_env/lib/python3.10/site-packages/h5py/_hl/files.py", line 564, in __init__
    fid = make_fid(name, mode, userblock_size, fapl, fcpl, swmr=swmr)
  File "/home/users/mmingyeong/.conda/envs/new_env/lib/python3.10/site-packages/h5py/_hl/files.py", line 244, in make_fid
    fid = h5f.create(name, h5f.ACC_TRUNC, fapl=fapl, fcpl=fcpl)
  File "h5py/_objects.pyx", line 54, in h5py._objects.with_phil.wrapper
  File "h5py/_objects.pyx", line 55, in h5py._objects.with_phil.wrapper
  File "h5py/h5f.pyx", line 122, in h5py.h5f.create
BlockingIOError: [Errno 11] Unable to synchronously create file (unable to lock file, errno = 11, error message = 'Resource temporarily unavailable')
