2025-04-21 14:53:58,512 - ERROR - Unhandled exception occurred:
Traceback (most recent call last):
  File "/caefs/user/mmingyeong/structura/Structura/src/example/density_kde_seq_chunks/00_TestDensity.py", line 148, in <module>
    main()
  File "/caefs/user/mmingyeong/structura/Structura/src/example/density_kde_seq_chunks/00_TestDensity.py", line 113, in main
    logger.info(f"Number of particles: {particles.shape[0]:,}")
  File "/home/users/mmingyeong/.conda/envs/new_env/lib/python3.10/site-packages/h5py/_hl/dataset.py", line 501, in shape
    shape = self.id.shape
  File "h5py/h5d.pyx", line 191, in h5py.h5d.DatasetID.shape.__get__
  File "h5py/h5d.pyx", line 192, in h5py.h5d.DatasetID.shape.__get__
  File "h5py/_objects.pyx", line 54, in h5py._objects.with_phil.wrapper
  File "h5py/_objects.pyx", line 55, in h5py._objects.with_phil.wrapper
  File "h5py/h5d.pyx", line 348, in h5py.h5d.DatasetID.get_space
RuntimeError: Unable to synchronously get dataspace (identifier is not of specified type)
