2025-04-21 13:55:41,554 - WARNING - GPU device 1 not accessible. Falling back to default device.
2025-04-21 13:55:41,556 - ERROR - Unhandled exception occurred:
Traceback (most recent call last):
  File "/caefs/user/mmingyeong/structura/Structura/src/config.py", line 62, in <module>
    cp.cuda.Device(GPU_DEVICE).use()
  File "cupy/cuda/device.pyx", line 185, in cupy.cuda.device.Device.use
  File "cupy/cuda/device.pyx", line 191, in cupy.cuda.device.Device.use
  File "cupy_backends/cuda/api/runtime.pyx", line 399, in cupy_backends.cuda.api.runtime.setDevice
  File "cupy_backends/cuda/api/runtime.pyx", line 146, in cupy_backends.cuda.api.runtime.check_status
cupy_backends.cuda.api.runtime.CUDARuntimeError: cudaErrorNoDevice: no CUDA-capable device is detected

During handling of the above exception, another exception occurred:

Traceback (most recent call last):
  File "/caefs/user/mmingyeong/structura/Structura/src/example/density_kde_seq_chunks/00_TestDensity.py", line 28, in <module>
    from config import OUTPUT_DATA_PATHS
  File "/caefs/user/mmingyeong/structura/Structura/src/config.py", line 68, in <module>
    cp.cuda.Device(0).use()
  File "cupy/cuda/device.pyx", line 185, in cupy.cuda.device.Device.use
  File "cupy/cuda/device.pyx", line 191, in cupy.cuda.device.Device.use
  File "cupy_backends/cuda/api/runtime.pyx", line 399, in cupy_backends.cuda.api.runtime.setDevice
  File "cupy_backends/cuda/api/runtime.pyx", line 146, in cupy_backends.cuda.api.runtime.check_status
cupy_backends.cuda.api.runtime.CUDARuntimeError: cudaErrorNoDevice: no CUDA-capable device is detected
