2025-04-21 14:44:42,961 - ERROR - Unhandled exception occurred:
Traceback (most recent call last):
  File "/caefs/user/mmingyeong/structura/Structura/src/example/density_kde_seq_chunks/00_TestDensity.py", line 136, in <module>
    main()
  File "/caefs/user/mmingyeong/structura/Structura/src/example/density_kde_seq_chunks/00_TestDensity.py", line 100, in main
    particles = hf['particles'][...]
  File "h5py/_objects.pyx", line 54, in h5py._objects.with_phil.wrapper
  File "h5py/_objects.pyx", line 55, in h5py._objects.with_phil.wrapper
  File "/home/users/mmingyeong/.conda/envs/new_env/lib/python3.10/site-packages/h5py/_hl/group.py", line 360, in __getitem__
    oid = h5o.open(self.id, self._e(name), lapl=self._lapl)
  File "h5py/_objects.pyx", line 54, in h5py._objects.with_phil.wrapper
  File "h5py/_objects.pyx", line 55, in h5py._objects.with_phil.wrapper
  File "h5py/h5o.pyx", line 257, in h5py.h5o.open
KeyError: "Unable to synchronously open object (object 'particles' doesn't exist)"
