2025-03-07 18:41:49,505 - INFO - Using GPU device 1.
2025-03-07 18:41:49,507 - INFO - Output directory 'TNG300_ICS' is set to: /caefs/data/IllustrisTNG/300/ICS
2025-03-07 18:41:49,507 - INFO - Output directory 'TNG300_snapshot99' is set to: /caefs/data/IllustrisTNG/snapshot-99-dm-npy/cache
2025-03-07 18:41:49,507 - WARNING - Output directory 'NPZ' does not exist: /path/to/your/output/npz
2025-03-07 18:41:49,507 - INFO - Output directory 'NPY' is set to: /caefs/data/IllustrisTNG/300/ICS
2025-03-07 18:41:49,507 - WARNING - Output directory 'LOGS' does not exist: /path/to/your/logs
2025-03-07 18:41:49,507 - INFO - Snapshot99 데이터 폴더: /caefs/data/IllustrisTNG/snapshot-99-dm-npy/cache
2025-03-07 18:41:49,507 - INFO - Output directory: /caefs/user/mmingyeong/structura/Structura/src/results
2025-03-07 18:41:49,507 - INFO - 전체 Snapshot99 데이터를 로드합니다...
2025-03-07 18:44:38,614 - INFO - Time elapsed for loading all data chunks: 169.10 seconds
2025-03-07 18:44:38,615 - INFO - Combined data shape: (0, 3)
2025-03-07 18:44:38,615 - ERROR - No data available after filtering. Please verify the filtering parameters or input files.
2025-03-07 18:44:38,616 - ERROR - Unhandled exception occurred:
Traceback (most recent call last):
  File "/caefs/user/mmingyeong/structura/Structura/src/example/density_ex.py", line 150, in <module>
    main()
  File "/caefs/user/mmingyeong/structura/Structura/src/example/density_ex.py", line 81, in main
    positions = loader.load_all_chunks(sampling_rate=1e-10)
  File "/caefs/user/mmingyeong/structura/Structura/src/data_loader.py", line 205, in load_all_chunks
    return cp.asarray(combined_np)
  File "/home/users/mmingyeong/.conda/envs/mingyeong310/lib/python3.10/site-packages/cupy/_creation/from_data.py", line 88, in asarray
    return _core.array(a, dtype, False, order, blocking=blocking)
  File "cupy/_core/core.pyx", line 2455, in cupy._core.core.array
  File "cupy/_core/core.pyx", line 2482, in cupy._core.core.array
  File "cupy/_core/core.pyx", line 2635, in cupy._core.core._array_default
  File "cupy/cuda/pinned_memory.pyx", line 357, in cupy.cuda.pinned_memory.is_memory_pinned
  File "cupy_backends/cuda/api/runtime.pyx", line 717, in cupy_backends.cuda.api.runtime.pointerGetAttributes
  File "cupy_backends/cuda/api/runtime.pyx", line 146, in cupy_backends.cuda.api.runtime.check_status
cupy_backends.cuda.api.runtime.CUDARuntimeError: cudaErrorInvalidValue: invalid argument
