2025-03-08 13:33:31,053 - INFO - GPU is available. CuPy will be used for FFT.
2025-03-08 13:33:32,186 - ERROR - Unhandled exception occurred:
Traceback (most recent call last):
  File "/home/users/mmingyeong/.conda/envs/new_env/lib/python3.10/runpy.py", line 196, in _run_module_as_main
    return _run_code(code, main_globals, None,
  File "/home/users/mmingyeong/.conda/envs/new_env/lib/python3.10/runpy.py", line 86, in _run_code
    exec(code, run_globals)
  File "/home/users/mmingyeong/.conda/envs/new_env/lib/python3.10/cProfile.py", line 191, in <module>
    main()
  File "/home/users/mmingyeong/.conda/envs/new_env/lib/python3.10/cProfile.py", line 180, in main
    runctx(code, globs, None, options.outfile, options.sort)
  File "/home/users/mmingyeong/.conda/envs/new_env/lib/python3.10/cProfile.py", line 20, in runctx
    return _pyprofile._Utils(Profile).runctx(statement, globals, locals,
  File "/home/users/mmingyeong/.conda/envs/new_env/lib/python3.10/profile.py", line 63, in runctx
    prof.runctx(statement, globals, locals)
  File "/home/users/mmingyeong/.conda/envs/new_env/lib/python3.10/cProfile.py", line 101, in runctx
    exec(cmd, globals, locals)
  File "fft_kde_ex.py", line 19, in <module>
    from data_loader import DataLoader
  File "/caefs/user/mmingyeong/structura/Structura/src/data_loader.py", line 8, in <module>
    from structura.logger import logger  # 공통 로거 가져오기
ModuleNotFoundError: No module named 'structura'
