2025-03-08 13:57:24,923 - INFO - GPU is available. CuPy will be used for FFT.
2025-03-08 13:57:25,474 - INFO - Using GPU device 1.
2025-03-08 13:57:25,474 - INFO - Output directory 'TNG300_ICS' is set to: /caefs/data/IllustrisTNG/300/ICS
2025-03-08 13:57:25,474 - INFO - Output directory 'TNG300_snapshot99' is set to: /caefs/data/IllustrisTNG/snapshot-99-dm-npy/cache
2025-03-08 13:57:25,474 - WARNING - Output directory 'NPZ' does not exist: /path/to/your/output/npz
2025-03-08 13:57:25,474 - INFO - Output directory 'NPY' is set to: /caefs/data/IllustrisTNG/300/ICS
2025-03-08 13:57:25,474 - WARNING - Output directory 'LOGS' does not exist: /path/to/your/logs
2025-03-08 13:57:25,474 - INFO - Snapshot99 데이터 폴더: /caefs/data/IllustrisTNG/snapshot-99-dm-npy/cache
2025-03-08 13:57:25,475 - INFO - Output directory: /caefs/user/mmingyeong/structura/Structura/src/results
2025-03-08 13:57:25,475 - INFO - 전체 Snapshot99 데이터를 로드합니다...
2025-03-08 14:50:20,312 - ERROR - Unhandled exception occurred:
concurrent.futures.process._RemoteTraceback: 
'''
Traceback (most recent call last):
  File "/home/users/mmingyeong/.conda/envs/new_env/lib/python3.10/concurrent/futures/process.py", line 392, in wait_result_broken_or_wakeup
    result_item = result_reader.recv()
  File "/home/users/mmingyeong/.conda/envs/new_env/lib/python3.10/multiprocessing/connection.py", line 250, in recv
    buf = self._recv_bytes()
  File "/home/users/mmingyeong/.conda/envs/new_env/lib/python3.10/multiprocessing/connection.py", line 421, in _recv_bytes
    return self._recv(size)
  File "/home/users/mmingyeong/.conda/envs/new_env/lib/python3.10/multiprocessing/connection.py", line 386, in _recv
    buf.write(chunk)
MemoryError
'''

The above exception was the direct cause of the following exception:

Traceback (most recent call last):
  File "/caefs/user/mmingyeong/structura/Structura/src/example/fft_kde_ex.py", line 96, in <module>
    main()
  File "/caefs/user/mmingyeong/structura/Structura/src/example/fft_kde_ex.py", line 35, in main
    positions = loader.load_all_chunks(sampling_rate=1)
  File "/caefs/user/mmingyeong/structura/Structura/src/data_loader.py", line 173, in load_all_chunks
    idx, chunk = future.result()
  File "/home/users/mmingyeong/.conda/envs/new_env/lib/python3.10/concurrent/futures/_base.py", line 451, in result
    return self.__get_result()
  File "/home/users/mmingyeong/.conda/envs/new_env/lib/python3.10/concurrent/futures/_base.py", line 403, in __get_result
    raise self._exception
concurrent.futures.process.BrokenProcessPool: A process in the process pool was terminated abruptly while the future was running or pending.
