2025-03-05 16:47:40,417 - INFO - ✅ Using GPU device 1.
2025-03-05 16:47:40,419 - WARNING - ⚠️ Output directory 'NPZ' does not exist: /path/to/your/output/npz
2025-03-05 16:47:40,419 - INFO - 📁 Output directory 'NPY' is set to: /caefs/data/IllustrisTNG/300/ICS
2025-03-05 16:47:40,419 - WARNING - ⚠️ Output directory 'LOGS' does not exist: /path/to/your/logs
2025-03-05 16:47:40,420 - INFO - 📁 Input (npy) folder: /caefs/data/IllustrisTNG/300/ICS
2025-03-05 16:47:40,421 - INFO - 📁 Output folder: /caefs/user/mmingyeong/structura/Structura/src/results
2025-03-05 16:47:40,422 - INFO - 📂 Detected 313 .npy files in the input folder.
2025-03-05 16:47:40,422 - INFO - 📄 Example file: chunk_89.npy
2025-03-05 16:47:40,422 - INFO - ✅ X range set: 64358.89 - 71133.51 ckpc/h (Center: 100 cMpc/h, Thickness: 10 cMpc/h)
2025-03-05 16:47:40,423 - INFO - 🔹 Filtering X range: 64358.89 - 71133.51 ckpc/h (64.359 - 71.134 cMpc/h)
2025-03-05 16:47:40,423 - INFO - 🔹 Loading data...
2025-03-05 16:51:21,985 - INFO - ✅ Time taken to load all chunks: 221.56s
2025-03-05 16:51:22,157 - INFO - ✅ Data loaded successfully. Shape: (5161333, 3)
2025-03-05 16:51:22,158 - INFO - 🔹 Generating 2D histogram, saving to ../results/...
2025-03-05 16:51:32,938 - ERROR - Unhandled exception occurred:
Traceback (most recent call last):
  File "/caefs/user/mmingyeong/structura/Structura/src/example/visualization_ex.py", line 61, in <module>
    viz.plot_2d_histogram(
  File "/caefs/user/mmingyeong/structura/Structura/src/visualization.py", line 67, in plot_2d_histogram
    im = ax.imshow(hist.T, origin='lower', extent=[yedges[0], yedges[-1], zedges[0], zedges[-1]], cmap=self.cmap, aspect='auto')
  File "/home/users/mmingyeong/.local/lib/python3.10/site-packages/matplotlib/__init__.py", line 1465, in inner
    return func(ax, *map(sanitize_sequence, args), **kwargs)
  File "/home/users/mmingyeong/.local/lib/python3.10/site-packages/matplotlib/axes/_axes.py", line 5769, in imshow
    im.set_extent(im.get_extent())
  File "/home/users/mmingyeong/.local/lib/python3.10/site-packages/matplotlib/image.py", line 985, in set_extent
    self.axes.update_datalim(corners)
  File "/home/users/mmingyeong/.local/lib/python3.10/site-packages/matplotlib/axes/_base.py", line 2509, in update_datalim
    xys = np.asarray(xys)
  File "cupy/_core/core.pyx", line 1528, in cupy._core.core._ndarray_base.__array__
TypeError: Implicit conversion to a NumPy array is not allowed. Please use `.get()` to construct a NumPy array explicitly.
